Workbook

Sheet Questionnaire
A1: Nimble Gravity AI-SDLC Maturity Assessment
A2: Answer every question Y or N based on what the client can evidence today, not what is planned. If it is true for some teams but not standard, answer N and note it. Then open Placement.
A3: Example: Q answered “Y” with note “seen in payments repo, CLAUDE.md v14” shows the expected format.
A5: TOOLS & SETUP
A6: 1 | B6: Has the organization issued sanctioned AI licenses and published an acceptable-use policy?
A7: 2 | B7: Is there a list of approved AI tools that procurement actually enforces?
A8: 3 | B8: Have personal or shadow AI accounts been migrated onto sanctioned tools?
A9: 4 | B9: Do repositories contain versioned AI configuration, such as context files or prompts, alongside the code?
A10: 5 | B10: Do new projects start from a standard AI-ready scaffold or template?
A11: 6 | B11: Do AI tools have governed access to internal documentation, code, and decision history?
A12: 7 | B12: Do agents run in sandboxed environments with scoped credentials?
A13: 8 | B13: Can any team stand up an agent pipeline on their own, inside governed boundaries?
A14: WAYS OF WORKING
A15: 9 | B15: Do individual engineers use AI assistants as part of their daily work?
A16: 10 | B16: Do recognized AI champions exist, even informally?
A17: 11 | B17: Are AI workflows documented with an owner, a trigger, and an expected output?
A18: 12 | B18: Is there at least one AI workflow whose configuration lives in version control and has been reproduced end to end by a second person?
A19: 13 | B19: Is there a regular forum where teams share AI workflows, including the failures?
A20: 14 | B20: Does onboarding for new engineers include the team’s AI workflows?
A21: 15 | B21: Do agent-eligible tickets carry a machine-readable definition of done?
A22: 16 | B22: Do ticket states distinguish work queued for, or in progress with, an agent?
A23: 17 | B23: Has at least one ticket been completed by an agent end to end, with humans approving only at defined checkpoints?
A24: 18 | B24: Are specs first-class artifacts that agents work from directly?
A25: 19 | B25: Is the backlog agent-ready by default, with human-only work as the exception?
A26: 20 | B26: Do dedicated roles exist for spec engineering or agent operations?
A27: QUALITY, REVIEW & SAFETY
A28: 21 | B28: Are there written review standards specifically for AI-assisted changes?
A29: 22 | B29: Is AI-generated content labeled with provenance in commits or pull requests?
A30: 23 | B30: Are norms for change size written down, so AI-generated work lands in small batches?
A31: 24 | B31: Does an automated verification harness, tests, static analysis, and policy checks, gate every merge?
A32: 25 | B32: Are boundaries documented for what agents may read, write, and never touch?
A33: 26 | B33: Have rollback procedures been exercised in practice, not just written?
A34: 27 | B34: Are engineers trained to review checkpoint evidence rather than reading every generated line?
A35: 28 | B35: Do eval suites run before any prompt or model change ships?
A36: 29 | B36: Are model versions pinned, with upgrades passing evaluation before rollout?
A37: 30 | B37: Is review effort triggered by signals rather than scheduled for everything?
A38: 31 | B38: Do drift alerts trigger automated rollback or rerouting when quality regresses?
A39: DATA, TELEMETRY & MEASUREMENT
A40: 32 | B40: Can you say which teams get value from AI, beyond seat counts and logins?
A41: 33 | B41: Is adoption tracked per workflow rather than per seat?
...

Sheet Map
A1: Row | B1: Dimension | C1: Level | D1: Gate | E1: Answer
A2: 6 | B2: Governance & Risk | C2: 1 | D2: 1 | E2: =Questionnaire!C6 -> 0
A3: 7 | B3: Governance & Risk | C3: 1 | D3: 0 | E3: =Questionnaire!C7 -> 0
A4: 8 | B4: Governance & Risk | C4: 1 | D4: 0 | E4: =Questionnaire!C8 -> 0
A5: 9 | B5: Platform & Tooling | C5: 2 | D5: 0 | E5: =Questionnaire!C9 -> 0
A6: 10 | B6: Platform & Tooling | C6: 2 | D6: 0 | E6: =Questionnaire!C10 -> 0
A7: 11 | B7: Platform & Tooling | C7: 3 | D7: 0 | E7: =Questionnaire!C11 -> 0
A8: 12 | B8: Platform & Tooling | C8: 3 | D8: 0 | E8: =Questionnaire!C12 -> 0
A9: 13 | B9: Platform & Tooling | C9: 5 | D9: 0 | E9: =Questionnaire!C13 -> 0
A10: 15 | B10: People & Skills | C10: 1 | D10: 0 | E10: =Questionnaire!C15 -> 0
A11: 16 | B11: People & Skills | C11: 1 | D11: 0 | E11: =Questionnaire!C16 -> 0
A12: 17 | B12: Process & Workflow | C12: 2 | D12: 0 | E12: =Questionnaire!C17 -> 0
A13: 18 | B13: Process & Workflow | C13: 2 | D13: 1 | E13: =Questionnaire!C18 -> 0
A14: 19 | B14: People & Skills | C14: 2 | D14: 0 | E14: =Questionnaire!C19 -> 0
A15: 20 | B15: People & Skills | C15: 2 | D15: 0 | E15: =Questionnaire!C20 -> 0
A16: 21 | B16: Process & Workflow | C16: 3 | D16: 0 | E16: =Questionnaire!C21 -> 0
A17: 22 | B17: Process & Workflow | C17: 3 | D17: 0 | E17: =Questionnaire!C22 -> 0
A18: 23 | B18: Process & Workflow | C18: 3 | D18: 1 | E18: =Questionnaire!C23 -> 0
A19: 24 | B19: Process & Workflow | C19: 5 | D19: 0 | E19: =Questionnaire!C24 -> 0
A20: 25 | B20: Process & Workflow | C20: 5 | D20: 0 | E20: =Questionnaire!C25 -> 0
A21: 26 | B21: People & Skills | C21: 5 | D21: 0 | E21: =Questionnaire!C26 -> 0
A22: 28 | B22: Governance & Risk | C22: 2 | D22: 0 | E22: =Questionnaire!C28 -> 0
A23: 29 | B23: Governance & Risk | C23: 2 | D23: 0 | E23: =Questionnaire!C29 -> 0
A24: 30 | B24: Process & Workflow | C24: 2 | D24: 0 | E24: =Questionnaire!C30 -> 0
A25: 31 | B25: Platform & Tooling | C25: 3 | D25: 0 | E25: =Questionnaire!C31 -> 0
A26: 32 | B26: Governance & Risk | C26: 3 | D26: 0 | E26: =Questionnaire!C32 -> 0
A27: 33 | B27: Governance & Risk | C27: 3 | D27: 0 | E27: =Questionnaire!C33 -> 0
A28: 34 | B28: People & Skills | C28: 3 | D28: 0 | E28: =Questionnaire!C34 -> 0
A29: 35 | B29: Measurement | C29: 4 | D29: 0 | E29: =Questionnaire!C35 -> 0
A30: 36 | B30: Governance & Risk | C30: 4 | D30: 0 | E30: =Questionnaire!C36 -> 0
A31: 37 | B31: Process & Workflow | C31: 5 | D31: 0 | E31: =Questionnaire!C37 -> 0
A32: 38 | B32: Platform & Tooling | C32: 5 | D32: 0 | E32: =Questionnaire!C38 -> 0
A33: 40 | B33: Measurement | C33: 2 | D33: 0 | E33: =Questionnaire!C40 -> 0
A34: 41 | B34: Measurement | C34: 2 | D34: 0 | E34: =Questionnaire!C41 -> 0
A35: 42 | B35: Platform & Tooling | C35: 3 | D35: 0 | E35: =Questionnaire!C42 -> 0
A36: 43 | B36: Measurement | C36: 3 | D36: 0 | E36: =Questionnaire!C43 -> 0
A37: 44 | B37: Platform & Tooling | C37: 4 | D37: 0 | E37: =Questionnaire!C44 -> 0
A38: 45 | B38: Platform & Tooling | C38: 4 | D38: 0 | E38: =Questionnaire!C45 -> 0
A39: 46 | B39: Measurement | C39: 4 | D39: 0 | E39: =Questionnaire!C46 -> 0
A40: 47 | B40: Measurement | C40: 4 | D40: 1 | E40: =Questionnaire!C47 -> 0
...

Sheet Placement
B2: Placement
B3: Nimble Gravity AI-SDLC Maturity Model
B5: Level evidence | C5: Evidence % | E5: Dimension profile (avg level of yes answers)
B6: Level 1: Ad Hoc | C6: =SUMPRODUCT((Map!$C$2:$C$50=1)*(Map!$E$2:$E$50="Y"))/SUMPRODUCT(--(Map!$C$2:$C$50=1)) -> 0 | E6: People & Skills | F6: =SUMPRODUCT((Map!$B$2:$B$50="People & Skills")*(Map!$E$2:$E$50="Y")*Map!$C$2:$C$50)/MAX(1,SUMPRODUCT((Map!$B$2:$B$50="People & Skills")*(Map!$E$2:$E$50="Y"))) -> 0
B7: Level 2: Defined | C7: =SUMPRODUCT((Map!$C$2:$C$50=2)*(Map!$E$2:$E$50="Y"))/SUMPRODUCT(--(Map!$C$2:$C$50=2)) -> 0 | E7: Process & Workflow | F7: =SUMPRODUCT((Map!$B$2:$B$50="Process & Workflow")*(Map!$E$2:$E$50="Y")*Map!$C$2:$C$50)/MAX(1,SUMPRODUCT((Map!$B$2:$B$50="Process & Workflow")*(Map!$E$2:$E$50="Y"))) -> 0
B8: Level 3: Managed Autonomy | C8: =SUMPRODUCT((Map!$C$2:$C$50=3)*(Map!$E$2:$E$50="Y"))/SUMPRODUCT(--(Map!$C$2:$C$50=3)) -> 0 | E8: Platform & Tooling | F8: =SUMPRODUCT((Map!$B$2:$B$50="Platform & Tooling")*(Map!$E$2:$E$50="Y")*Map!$C$2:$C$50)/MAX(1,SUMPRODUCT((Map!$B$2:$B$50="Platform & Tooling")*(Map!$E$2:$E$50="Y"))) -> 0
B9: Level 4: Quantitatively Managed | C9: =SUMPRODUCT((Map!$C$2:$C$50=4)*(Map!$E$2:$E$50="Y"))/SUMPRODUCT(--(Map!$C$2:$C$50=4)) -> 0 | E9: Governance & Risk | F9: =SUMPRODUCT((Map!$B$2:$B$50="Governance & Risk")*(Map!$E$2:$E$50="Y")*Map!$C$2:$C$50)/MAX(1,SUMPRODUCT((Map!$B$2:$B$50="Governance & Risk")*(Map!$E$2:$E$50="Y"))) -> 0
B10: Level 5: Optimizing | C10: =SUMPRODUCT((Map!$C$2:$C$50=5)*(Map!$E$2:$E$50="Y"))/SUMPRODUCT(--(Map!$C$2:$C$50=5)) -> 0 | E10: Measurement | F10: =SUMPRODUCT((Map!$B$2:$B$50="Measurement")*(Map!$E$2:$E$50="Y")*Map!$C$2:$C$50)/MAX(1,SUMPRODUCT((Map!$B$2:$B$50="Measurement")*(Map!$E$2:$E$50="Y"))) -> 0
B13: Gate ceiling | C13: =IF(SUMPRODUCT((Map!$C$2:$C$50=1)*(Map!$D$2:$D$50=1)*(Map!$E$2:$E$50="Y"))=1,1+IF(SUMPRODUCT((Map!$C$2:$C$50=2)*(Map!$D$2:$D$50=1)*(Map!$E$2:$E$50="Y"))=1,1+IF(SUMPRODUCT((Map!$C$2:$C$50=3)*(Map!$D$2:$D$50=1)*(Map!$E$2:$E$50="Y"))=1,1+IF(SUMPRODUCT((Map!$C$2:$C$50=4)*(Map!$D$2:$D$50=1)*(Map!$E$2:$E$50="Y"))=1,1+IF(SUMPRODUCT((Map!$C$2:$C$50=5)*(Map!$D$2:$D$50=1)*(Map!$E$2:$E$50="Y"))=1,1,0),0),0),0),0) -> 0 | E13: The ladder
B14: Evidence ceiling (60% rule) | C14: =IF(C6>=0.6,1+IF(C7>=0.6,1+IF(C8>=0.6,1+IF(C9>=0.6,1+IF(C10>=0.6,1,0),0),0),0),0) -> 0 | E14: Level 5: Optimizing | F14: =IF($C$16=5,"◀ YOU ARE HERE","")
E15: Level 4: Quantitatively Managed | F15: =IF($C$16=4,"◀ YOU ARE HERE","")
B16: PLACED LEVEL | C16: =MIN(C13,C14) -> 0 | E16: Level 3: Managed Autonomy | F16: =IF($C$16=3,"◀ YOU ARE HERE","")
B17: =INDEX({"No AI Use";"Ad Hoc";"Defined";"Managed Autonomy";"Quantitatively Managed";"Optimizing"},C16+1) -> No AI Use | E17: Level 2: Defined | F17: =IF($C$16=2,"◀ YOU ARE HERE","")
E18: Level 1: Ad Hoc | F18: =IF($C$16=1,"◀ YOU ARE HERE","")
B19: =IF(C16=5,"Diagnosis: operating at the top of the model. The work is holding it.",IF(C13<C14,"Diagnosis: practices outrun the gates. Evidence of higher-level behavior exists ("&SUMPRODUCT((Map!$C$2:$C$50>C16)*(Map!$E$2:$E$50="Y"))&" yes answers above the placed level), but gate "&C13+1&" has not happened. Close that gate.",IF(SUMPRODUCT((Map!$C$2:$C$50>C16)*(Map!$E$2:$E$50="Y"))>=4,"Diagnosis: pockets of higher-level practice exist ("&SUMPRODUCT((Map!$C$2:$C$50>C16)*(Map!$E$2:$E$50="Y"))&" yes answers above the placed level). Spread and standardize before reaching further.","Diagnosis: balanced profile. The path forward is the exit gate of the current level."))) -> Diagnosis: balanced profile. The path forward is the exit gate of the current level. | E19: Level 0: No AI Use | F19: =IF($C$16=0,"◀ YOU ARE HERE","") -> ◀ YOU ARE HERE
B24: Placed level = the lower of the gate ceiling (highest consecutive gate evidenced) and the evidence ceiling (highest consecutive level with at least 60% of its questions answered yes).

Sheet Sources
A1: Research behind the question bank
A3: DORA AI Capabilities Model (Google, 2025, v2025.1) | B3: Seven capabilities that amplify AI: clear AI stance, healthy data ecosystems, AI-accessible internal data, strong version control, small batches, user-centric focus, quality internal platforms. dora.dev/ai/capabilities-model
A4: DORA ROI of AI-assisted Software Development (2026) | B4: Verification tax and instability tax; warns against adoption percentages and token counts as goals. dora.dev/research/publications
A5: DORA five-metric delivery model (2026) | B5: Four keys plus deployment rework rate as delivery ground truth. dora.dev
A6: DORA Insights on tokenmaxxing (Jun 2026) | B6: Rewarding raw token consumption is an anti-metric; informs the banned-metrics question. dora.dev/insights
A7: OpenTelemetry GenAI semantic conventions / OpenInference | B7: Standard span schema for prompts, tool calls, retrievals, agent steps, with token, cost, and eval attributes.
A8: Agent observability practice (2026 industry guides) | B8: Layered evaluation (unit, judge, production sampling); cost tagged at request creation; drift alerts, automated rollback, kill switches.
A10: Question wording is original; sources informed which behaviors indicate experience.
